Traceback (most recent call last):
  File "melanoma_classifier.py", line 283, in <module>
    test_df = load_test_isic(args.path_real_imgs_test, args.path_real_imgs_test)
  File "/ISIC256/project_scripts/GITHUB_REPO/Generative_modelling_for_melanoma_detection/stylegan2-ada-pytorch/utils.py", line 389, in load_test_isic
    df = pd.read_csv(csv_path)
  File "/usr/local/lib/python3.8/dist-packages/pandas/util/_decorators.py", line 311, in wrapper
    return func(*args, **kwargs)
  File "/usr/local/lib/python3.8/dist-packages/pandas/io/parsers/readers.py", line 680, in read_csv
    return _read(filepath_or_buffer, kwds)
  File "/usr/local/lib/python3.8/dist-packages/pandas/io/parsers/readers.py", line 575, in _read
    parser = TextFileReader(filepath_or_buffer, **kwds)
  File "/usr/local/lib/python3.8/dist-packages/pandas/io/parsers/readers.py", line 933, in __init__
    self._engine = self._make_engine(f, self.engine)
  File "/usr/local/lib/python3.8/dist-packages/pandas/io/parsers/readers.py", line 1217, in _make_engine
    self.handles = get_handle(  # type: ignore[call-overload]
  File "/usr/local/lib/python3.8/dist-packages/pandas/io/common.py", line 789, in get_handle
    handle = open(
IsADirectoryError: [Errno 21] Is a directory: '/ISIC256/train_ISIC256_orig/val_set'