2022-04-13 10:47:29,352 INFO    MainThread:26756 [internal.py:wandb_internal():92] W&B internal server running at pid: 26756, started at: 2022-04-13 10:47:29.351385
2022-04-13 10:47:29,355 INFO    WriterThread:26756 [datastore.py:open_for_write():77] open: /ISIC256/project_scripts/GITHUB_REPO/Generative_modelling_for_melanoma_detection/stylegan2-ada-pytorch/wandb/run-20220413_104728-6rtkn2dv/run-6rtkn2dv.wandb
2022-04-13 10:47:29,356 DEBUG   SenderThread:26756 [sender.py:send():235] send: header
2022-04-13 10:47:29,356 DEBUG   SenderThread:26756 [sender.py:send():235] send: run
2022-04-13 10:47:29,545 ERROR   SenderThread:26756 [internal_api.py:execute():144] 404 response executing GraphQL.
2022-04-13 10:47:29,545 ERROR   SenderThread:26756 [internal_api.py:execute():145] {"errors":[{"message":"entity chalmers not found during upsertBucket","path":["upsertBucket"]}],"data":{"upsertBucket":null}}
2022-04-13 10:47:30,356 INFO    HandlerThread:26756 [handler.py:finish():790] shutting down handler
2022-04-13 10:47:30,356 INFO    WriterThread:26756 [datastore.py:close():281] close: /ISIC256/project_scripts/GITHUB_REPO/Generative_modelling_for_melanoma_detection/stylegan2-ada-pytorch/wandb/run-20220413_104728-6rtkn2dv/run-6rtkn2dv.wandb
2022-04-13 10:47:30,358 ERROR   MainThread:26756 [internal.py:wandb_internal():167] Thread SenderThread:
Traceback (most recent call last):
  File "/usr/local/lib/python3.8/dist-packages/wandb/sdk/lib/retry.py", line 102, in __call__
    result = self._call_fn(*args, **kwargs)
  File "/usr/local/lib/python3.8/dist-packages/wandb/sdk/internal/internal_api.py", line 147, in execute
    six.reraise(*sys.exc_info())
  File "/usr/lib/python3/dist-packages/six.py", line 703, in reraise
    raise value
  File "/usr/local/lib/python3.8/dist-packages/wandb/sdk/internal/internal_api.py", line 141, in execute
    return self.client.execute(*args, **kwargs)
  File "/usr/local/lib/python3.8/dist-packages/wandb/vendor/gql-0.2.0/wandb_gql/client.py", line 52, in execute
    result = self._get_result(document, *args, **kwargs)
  File "/usr/local/lib/python3.8/dist-packages/wandb/vendor/gql-0.2.0/wandb_gql/client.py", line 60, in _get_result
    return self.transport.execute(document, *args, **kwargs)
  File "/usr/local/lib/python3.8/dist-packages/wandb/vendor/gql-0.2.0/wandb_gql/transport/requests.py", line 39, in execute
    request.raise_for_status()
  File "/usr/lib/python3/dist-packages/requests/models.py", line 940, in raise_for_status
    raise HTTPError(http_error_msg, response=self)
requests.exceptions.HTTPError: 404 Client Error: Not Found for url: https://api.wandb.ai/graphql

During handling of the above exception, another exception occurred:

Traceback (most recent call last):
  File "/usr/local/lib/python3.8/dist-packages/wandb/apis/normalize.py", line 24, in wrapper
    return func(*args, **kwargs)
  File "/usr/local/lib/python3.8/dist-packages/wandb/sdk/internal/internal_api.py", line 1315, in upsert_run
    response = self.gql(mutation, variable_values=variable_values, **kwargs)
  File "/usr/local/lib/python3.8/dist-packages/wandb/sdk/lib/retry.py", line 118, in __call__
    if not check_retry_fn(e):
  File "/usr/local/lib/python3.8/dist-packages/wandb/util.py", line 873, in no_retry_auth
    raise CommError("Permission denied, ask the project owner to grant you access")
wandb.errors.CommError: Permission denied, ask the project owner to grant you access

During handling of the above exception, another exception occurred:

Traceback (most recent call last):
  File "/usr/local/lib/python3.8/dist-packages/wandb/sdk/internal/internal_util.py", line 54, in run
    self._run()
  File "/usr/local/lib/python3.8/dist-packages/wandb/sdk/internal/internal_util.py", line 105, in _run
    self._process(record)
  File "/usr/local/lib/python3.8/dist-packages/wandb/sdk/internal/internal.py", line 312, in _process
    self._sm.send(record)
  File "/usr/local/lib/python3.8/dist-packages/wandb/sdk/internal/sender.py", line 237, in send
    send_handler(record)
  File "/usr/local/lib/python3.8/dist-packages/wandb/sdk/internal/sender.py", line 695, in send_run
    self._init_run(run, config_value_dict)
  File "/usr/local/lib/python3.8/dist-packages/wandb/sdk/internal/sender.py", line 719, in _init_run
    server_run, inserted = self._api.upsert_run(
  File "/usr/local/lib/python3.8/dist-packages/wandb/apis/normalize.py", line 62, in wrapper
    six.reraise(CommError, CommError(message, err), sys.exc_info()[2])
  File "/usr/lib/python3/dist-packages/six.py", line 702, in reraise
    raise value.with_traceback(tb)
  File "/usr/local/lib/python3.8/dist-packages/wandb/apis/normalize.py", line 24, in wrapper
    return func(*args, **kwargs)
  File "/usr/local/lib/python3.8/dist-packages/wandb/sdk/internal/internal_api.py", line 1315, in upsert_run
    response = self.gql(mutation, variable_values=variable_values, **kwargs)
  File "/usr/local/lib/python3.8/dist-packages/wandb/sdk/lib/retry.py", line 118, in __call__
    if not check_retry_fn(e):
  File "/usr/local/lib/python3.8/dist-packages/wandb/util.py", line 873, in no_retry_auth
    raise CommError("Permission denied, ask the project owner to grant you access")
wandb.errors.CommError: Permission denied, ask the project owner to grant you access
2022-04-13 10:47:32,374 INFO    MainThread:26756 [internal.py:handle_exit():82] Internal process exited
